#VRML_SIM R2023a utf8

EXTERNPROTO "https://raw.githubusercontent.com/cyberbotics/webots/R2023a/projects/objects/floors/protos/CircleArena.proto"

WorldInfo {
  ERP 0.8
  basicTimeStep 5
  dragForceScale 1000
  contactProperties [
    ContactProperties {
    }
  ]
}
Viewpoint {
  orientation -0.131241568177067 0.06182234708343618 0.9894208650435463 2.2693114433874726
  position -0.16524202695651424 -1.6992537345014973 0.8491964366764116
  follow "circle arena"
}
TexturedBackground {
}
TexturedBackgroundLight {
}
CircleArena {
  radius 100
}
DEF TITA Robot {
  translation -1.7 0 0.22
  rotation 0 1 0 4.692820414042842e-06
  children [
    GPS {
    }
    Gyro {
    }
    InertialUnit {
      name "imu"
    }
    Accelerometer {
      name "accl"
    }
    Shape {
      appearance DEF pelvis_material PBRAppearance {
        baseColor 0.75294 0.75294 0.75294
        roughness 1
        metalness 0
      }
      geometry DEF pelvis Mesh {
        url [
          "../urdfs/meshes/pelvis.STL"
        ]
      }
    }
    HingeJoint {
      jointParameters HingeJointParameters {
        axis 1 0 -4e-06
        anchor 0 0.0895 0
      }
      device [
        RotationalMotor {
          name "left_hip_abduction_joint"
          minPosition -1.57
          maxPosition 1.57
          maxTorque 10000
        }
        PositionSensor {
          name "left_hip_abduction_joint_sensor"
        }
      ]
      endPoint DEF LEFT_HIP Solid {
        translation 0 0.0895 0
        rotation -1.3747844855604792e-16 1 -1.2266324805124255e-18 1.5707999999999982
        children [
          Shape {
            appearance DEF left_hip_material PBRAppearance {
              baseColor 0.75294 0.75294 0.75294
              roughness 1
              metalness 0
            }
            geometry DEF left_hip Mesh {
              url [
                "../urdfs/meshes/left_hip.STL"
              ]
            }
          }
          HingeJoint {
            jointParameters HingeJointParameters {
              position 1.2
              axis 0 1 0
              anchor 0 0.1826 0
            }
            device [
              RotationalMotor {
                name "left_hip_flexion_joint"
                minPosition -1.57
                maxPosition 1.57
                maxTorque 10000
              }
              PositionSensor {
                name "left_hip_flexion_joint_sensor"
              }
            ]
            endPoint DEF LEFT_THIGH Solid {
              translation 0 0.1826 0
              rotation -0.7186840800387236 0.4916764266920013 0.4916782327236774 1.8952844091080387
              children [
                Shape {
                  appearance DEF left_thigh_material PBRAppearance {
                    baseColor 0.75294 0.75294 0.75294
                    roughness 1
                    metalness 0
                  }
                  geometry DEF left_thigh Mesh {
                    url [
                      "../urdfs/meshes/left_thigh.STL"
                    ]
                  }
                }
                HingeJoint {
                  jointParameters HingeJointParameters {
                    position -0.9
                    axis 0 0 1
                    anchor 0.2 0 0
                    minStop -1.1
                    maxStop 0.85
                  }
                  device [
                    RotationalMotor {
                      name "left_knee_joint"
                      maxTorque 10000
                    }
                    PositionSensor {
                      name "left_knee_joint_sensor"
                    }
                  ]
                  endPoint DEF LEFT_CALF Solid {
                    translation 0.2 0 0
                    rotation 0 0 -1 2.4708003061004233
                    children [
                      Shape {
                        appearance DEF left_calf_material PBRAppearance {
                          baseColor 0.75294 0.75294 0.75294
                          roughness 1
                          metalness 0
                        }
                        geometry DEF left_calf Mesh {
                          url [
                            "../urdfs/meshes/left_calf.STL"
                          ]
                        }
                      }
                      HingeJoint {
                        jointParameters HingeJointParameters {
                          axis 0 0 1
                          anchor 0.2 0 0
                        }
                        device [
                          RotationalMotor {
                            name "left_ankle_joint"
                            maxTorque 10000
                          }
                          PositionSensor {
                            name "left_ankle_joint_sensor"
                          }
                        ]
                        endPoint DEF LEFT_WHEEL Solid {
                          translation 0.2 0 0
                          children [
                            Shape {
                              appearance DEF left_wheel_material PBRAppearance {
                                baseColor 0.69804 0.69804 0.69804
                                roughness 1
                                metalness 0
                              }
                              geometry DEF left_wheel Mesh {
                                url [
                                  "../urdfs/meshes/left_wheel.STL"
                                ]
                              }
                            }
                          ]
                          name "left_wheel"
                          contactMaterial "wheel"
                          boundingObject Cylinder {
                            height 0.034
                            radius 0.088
                          }
                          physics DEF LEFT_WHEEL_PHYSICS Physics {
                            density -1
                            mass 1.5376
                            centerOfMass [
                              -1.6e-05 0.000206 -0.001793
                            ]
                            inertiaMatrix [
                              0.0031616 0.0031569 0.0061689
                              1.6324e-07 -4.4034e-08 -2.2207e-06
                            ]
                          }
                        }
                      }
                    ]
                    name "left_calf"
                    boundingObject Transform {
                      translation 0.1 0.021 -0.058
                      rotation 0 0 1 -0.13090030610042527
                      children [
                        Box {
                          size 0.2 0.07 0.05
                        }
                      ]
                    }
                    physics DEF LEFT_CALF_PHYSICS Physics {
                      density -1
                      mass 0.6116
                      centerOfMass [
                        0.12103 0.009076 -0.050402
                      ]
                      inertiaMatrix [
                        0.00026451 0.0021601 0.0023188
                        0.0001824 -2.3439e-05 -3.2211e-07
                      ]
                    }
                  }
                }
              ]
              name "left_thigh"
              physics DEF LEFT_THIGH_PHYSICS Physics {
                density -1
                mass 2.365
                centerOfMass [
                  0.019003 0.000924 -0.091109
                ]
                inertiaMatrix [
                  0.0024777 0.0052687 0.0067964
                  -0.00013332 0.00010713 5.2693e-06
                ]
              }
            }
          }
        ]
        name "left_hip"
        physics DEF LEFT_HIP_PHYSICS Physics {
          density -1
          mass 1.9732
          centerOfMass [
            -4.4e-05 -0.014041 0.002749
          ]
          inertiaMatrix [
            0.002746 0.0040655 0.0021042
            2.2481e-07 4.8998e-07 3.5899e-05
          ]
        }
      }
    }
    HingeJoint {
      jointParameters HingeJointParameters {
        axis 1 0 -4e-06
        anchor 0 -0.0895 0
      }
      device [
        RotationalMotor {
          name "right_hip_abduction_joint"
          minPosition -1.57
          maxPosition 1.57
          maxTorque 10000
        }
        PositionSensor {
          name "right_hip_abduction_joint_sensor"
        }
      ]
      endPoint DEF RIGHT_HIP Solid {
        translation 0 -0.0895 0
        rotation 1.2986809018089848e-16 1 -1.2266324805124253e-18 1.5707999999999989
        children [
          Shape {
            appearance DEF right_hip_material PBRAppearance {
              baseColor 0.75294 0.75294 0.75294
              roughness 1
              metalness 0
            }
            geometry DEF right_hip Mesh {
              url [
                "../urdfs/meshes/right_hip.STL"
              ]
            }
          }
          HingeJoint {
            jointParameters HingeJointParameters {
              position 1.2
              axis 0 1 -4e-06
              anchor 0 -0.1826 0
            }
            device [
              RotationalMotor {
                name "right_hip_flexion_joint"
                minPosition -1.57
                maxPosition 1.57
                maxTorque 10000
              }
              PositionSensor {
                name "right_hip_flexion_joint_sensor"
              }
            ]
            endPoint DEF RIGHT_THIGH Solid {
              translation 0 -0.1826 0
              rotation -0.7186840800387234 0.4916783934009995 0.49167626601403686 1.8952844091080372
              children [
                Shape {
                  appearance DEF right_thigh_material PBRAppearance {
                    baseColor 0.75294 0.75294 0.75294
                    roughness 1
                    metalness 0
                  }
                  geometry DEF right_thigh Mesh {
                    url [
                      "../urdfs/meshes/right_thigh.STL"
                    ]
                  }
                }
                HingeJoint {
                  jointParameters HingeJointParameters {
                    position -0.9
                    axis 0 0 1
                    anchor 0.2 0 0
                    minStop -1.1
                    maxStop 0.85
                  }
                  device [
                    RotationalMotor {
                      name "right_knee_joint"
                      maxTorque 10000
                    }
                    PositionSensor {
                      name "right_knee_joint_sensor"
                    }
                  ]
                  endPoint DEF RIGHT_CALF Solid {
                    translation 0.2 0 0
                    rotation 0 0 -1 2.470799999999996
                    children [
                      Shape {
                        appearance DEF right_calf_material PBRAppearance {
                          baseColor 0.75294 0.75294 0.75294
                          roughness 1
                          metalness 0
                        }
                        geometry DEF right_calf Mesh {
                          url [
                            "../urdfs/meshes/right_calf.STL"
                          ]
                        }
                      }
                      HingeJoint {
                        jointParameters HingeJointParameters {
                          axis 0 0 1
                          anchor 0.2 0 0
                        }
                        device [
                          RotationalMotor {
                            name "right_ankle_joint"
                            maxTorque 10000
                          }
                          PositionSensor {
                            name "right_ankle_joint_sensor"
                          }
                        ]
                        endPoint DEF RIGHT_WHEEL Solid {
                          translation 0.2 0 0
                          children [
                            Shape {
                              appearance DEF right_wheel_material PBRAppearance {
                                baseColor 0.69804 0.69804 0.69804
                                roughness 1
                                metalness 0
                              }
                              geometry DEF right_wheel Mesh {
                                url [
                                  "../urdfs/meshes/right_wheel.STL"
                                ]
                              }
                            }
                          ]
                          name "right_wheel"
                          contactMaterial "wheel"
                          boundingObject Cylinder {
                            height 0.034
                            radius 0.088
                          }
                          physics DEF RIGHT_WHEEL_PHYSICS Physics {
                            density -1
                            mass 1.5377
                            centerOfMass [
                              0 4.2e-05 0.001845
                            ]
                            inertiaMatrix [
                              0.003086 0.003086 0.0059413
                              4.7536e-08 3.5434e-08 -4.621e-08
                            ]
                          }
                        }
                      }
                    ]
                    name "right_calf"
                    boundingObject Transform {
                      translation 0.1 0.021 0.058
                      rotation 0 0 1 -0.13090030610042527
                      children [
                        Box {
                          size 0.2 0.07 0.05
                        }
                      ]
                    }
                    physics DEF RIGHT_CALF_PHYSICS Physics {
                      density -1
                      mass 0.6116
                      centerOfMass [
                        0.12103 0.0091 0.05039
                      ]
                      inertiaMatrix [
                        0.00026444 0.0021602 0.0023188
                        0.00018202 2.3441e-05 3.2666e-07
                      ]
                    }
                  }
                }
              ]
              name "right_thigh"
              physics DEF RIGHT_THIGH_PHYSICS Physics {
                density -1
                mass 2.365
                centerOfMass [
                  0.018988 0.000908 0.091109
                ]
                inertiaMatrix [
                  0.0024783 0.0052682 0.0067965
                  -0.00013332 -0.00010721 -5.356e-06
                ]
              }
            }
          }
        ]
        name "right_hip"
        physics DEF RIGHT_HIP_PHYSICS Physics {
          density -1
          mass 1.9732
          centerOfMass [
            4.4e-05 0.014041 0.002749
          ]
          inertiaMatrix [
            0.002746 0.0040655 0.0021042
            2.2481e-07 -4.8998e-07 -3.5899e-05
          ]
        }
      }
    }
  ]
  name "TitaV2(1)"
  boundingObject Transform {
    translation 0 0 0.017
    children [
      Box {
        size 0.47 0.3 0.19
      }
    ]
  }
  physics DEF TITA_PHYSICS Physics {
    density -1
    mass 11.637
    centerOfMass [
      -0.002847 -0.000372 0.01809
    ]
    inertiaMatrix [
      0.047811 0.031456 0.057429
      -1.1402e-05 0.0006116 1.4971e-05
    ]
  }
  controller "<extern>"
  supervisor TRUE
}
Solid {
  translation 0 0 -0.29
  children [
    Solid {
      children [
        Shape {
          appearance PBRAppearance {
            baseColor 0.305882 0.603922 0.0235294
          }
          geometry Box {
            size 0.17 1.8 0.15
          }
        }
      ]
      boundingObject Box {
        size 0.17 1.8 0.15
      }
    }
  ]
  name "solid(1)"
}
