<?xml version="1.0" encoding="utf-8"?>
<!-- This URDF was automatically created by SolidWorks to URDF Exporter! Originally created by Stephen Brawner (brawner@gmail.com) 
     Commit Version: 1.6.0-4-g7f85cfe  Build Version: 1.6.7995.38578
     For more information, please see http://wiki.ros.org/sw_urdf_exporter -->
<robot
  name="titaV2">
  <link
    name="pelvis">
    <inertial>
      <origin
        xyz="-0.002847 -0.00037169 0.01809"
        rpy="0 0 0" />
      <mass
        value="11.637" />
      <inertia
        ixx="0.047811"
        ixy="-1.1402E-05"
        ixz="0.0006116"
        iyy="0.031456"
        iyz="1.4971E-05"
        izz="0.057429" />
    </inertial>
    <visual>
      <origin
        xyz="0 0 0"
        rpy="0 0 0" />
      <geometry>
        <mesh
          filename="package://titaV2/meshes/pelvis.STL" />
      </geometry>
      <material
        name="">
        <color
          rgba="0.75294 0.75294 0.75294 1" />
      </material>
    </visual>
    <collision>
      <origin
        xyz="0 0 0"
        rpy="0 0 0" />
      <geometry>
        <mesh
          filename="package://titaV2/meshes/pelvis.STL" />
      </geometry>
    </collision>
  </link>
  <link
    name="tof">
  </link>
  <joint
    name="tof"
    type="fixed">
    <origin
      xyz="0.24052 -0.0019 0.064455"
      rpy="2.199 0 1.5708" />
    <parent
      link="pelvis" />
    <child
      link="tof" />
    <axis
      xyz="0 0 0" />
  </joint>
  <link
    name="left_camera">
  </link>
  <joint
    name="left_camera"
    type="fixed">
    <origin
      xyz="0.23416 0.075 0.04036"
      rpy="1.5708 0 1.5708" />
    <parent
      link="pelvis" />
    <child
      link="left_camera" />
    <axis
      xyz="0 0 0" />
  </joint>
  <link
    name="ch201">
  </link>
  <joint
    name="ch201"
    type="fixed">
    <origin
      xyz="0.23782 0 0.018636"
      rpy="1.1693 0 1.5708" />
    <parent
      link="pelvis" />
    <child
      link="ch201" />
    <axis
      xyz="0 0 0" />
  </joint>
  <link
    name="right_camara">
  </link>
  <joint
    name="right_camera"
    type="fixed">
    <origin
      xyz="0.23416 -0.075001 0.04036"
      rpy="1.5708 0 1.5708" />
    <parent
      link="pelvis" />
    <child
      link="right_camara" />
    <axis
      xyz="0 0 0" />
  </joint>
  <link
    name="left_hip">
    <inertial>
      <origin
        xyz="-4.4311E-05 -0.014041 0.0027491"
        rpy="0 0 0" />
      <mass
        value="1.9732" />
      <inertia
        ixx="0.002746"
        ixy="2.2481E-07"
        ixz="4.8998E-07"
        iyy="0.0040655"
        iyz="3.5899E-05"
        izz="0.0021042" />
    </inertial>
    <visual>
      <origin
        xyz="0 0 0"
        rpy="0 0 0" />
      <geometry>
        <mesh
          filename="package://titaV2/meshes/left_hip.STL" />
      </geometry>
      <material
        name="">
        <color
          rgba="0.75294 0.75294 0.75294 1" />
      </material>
    </visual>
    <collision>
      <origin
        xyz="0 0 0"
        rpy="0 0 0" />
      <geometry>
        <mesh
          filename="package://titaV2/meshes/left_hip.STL" />
      </geometry>
    </collision>
  </link>
  <joint
    name="left_hip_abduction_joint"
    type="revolute">
    <origin
      xyz="0 0.0895 0"
      rpy="0 1.5708 0" />
    <parent
      link="pelvis" />
    <child
      link="left_hip" />
    <axis
      xyz="0 0 1" />
    <limit
      lower="-1.57"
      upper="1.57"
      effort="0"
      velocity="0" />
  </joint>
  <link
    name="left_thigh">
    <inertial>
      <origin
        xyz="0.019003 0.00092368 -0.091109"
        rpy="0 0 0" />
      <mass
        value="2.365" />
      <inertia
        ixx="0.0024777"
        ixy="-0.00013332"
        ixz="0.00010713"
        iyy="0.0052687"
        iyz="5.2693E-06"
        izz="0.0067964" />
    </inertial>
    <visual>
      <origin
        xyz="0 0 0"
        rpy="0 0 0" />
      <geometry>
        <mesh
          filename="package://titaV2/meshes/left_thigh.STL" />
      </geometry>
      <material
        name="">
        <color
          rgba="0.75294 0.75294 0.75294 1" />
      </material>
    </visual>
    <collision>
      <origin
        xyz="0 0 0"
        rpy="0 0 0" />
      <geometry>
        <mesh
          filename="package://titaV2/meshes/left_thigh.STL" />
      </geometry>
    </collision>
  </link>
  <joint
    name="left_hip_flexion_joint"
    type="revolute">
    <origin
      xyz="0 0.1826 0"
      rpy="-1.5708 0 0" />
    <parent
      link="left_hip" />
    <child
      link="left_thigh" />
    <axis
      xyz="0 0 1" />
    <limit
      lower="-1.57"
      upper="1.57"
      effort="0"
      velocity="0" />
  </joint>
  <link
    name="left_calf">
    <inertial>
      <origin
        xyz="0.12103 0.0090757 -0.050402"
        rpy="0 0 0" />
      <mass
        value="0.6116" />
      <inertia
        ixx="0.00026451"
        ixy="0.0001824"
        ixz="-2.3439E-05"
        iyy="0.0021601"
        iyz="-3.2211E-07"
        izz="0.0023188" />
    </inertial>
    <visual>
      <origin
        xyz="0 0 0"
        rpy="0 0 0" />
      <geometry>
        <mesh
          filename="package://titaV2/meshes/left_calf.STL" />
      </geometry>
      <material
        name="">
        <color
          rgba="0.75294 0.75294 0.75294 1" />
      </material>
    </visual>
    <collision>
      <origin
        xyz="0 0 0"
        rpy="0 0 0" />
      <geometry>
        <mesh
          filename="package://titaV2/meshes/left_calf.STL" />
      </geometry>
    </collision>
  </link>
  <joint
    name="left_knee_joint"
    type="revolute">
    <origin
      xyz="0.2 0 0"
      rpy="0 0 0" />
    <parent
      link="left_thigh" />
    <child
      link="left_calf" />
    <axis
      xyz="0 0 1" />
    <limit
      lower="-2"
      upper="1"
      effort="0"
      velocity="0" />
  </joint>
  <link
    name="left_wheel">
    <inertial>
      <origin
        xyz="-1.5738E-05 0.00020568 -0.0017928"
        rpy="0 0 0" />
      <mass
        value="1.5376" />
      <inertia
        ixx="0.0031616"
        ixy="1.6324E-07"
        ixz="-4.4034E-08"
        iyy="0.0031569"
        iyz="-2.2207E-06"
        izz="0.0061689" />
    </inertial>
    <visual>
      <origin
        xyz="0 0 0"
        rpy="0 0 0" />
      <geometry>
        <mesh
          filename="package://titaV2/meshes/left_wheel.STL" />
      </geometry>
      <material
        name="">
        <color
          rgba="0.69804 0.69804 0.69804 1" />
      </material>
    </visual>
    <collision>
      <origin
        xyz="0 0 0"
        rpy="0 0 0" />
      <geometry>
        <mesh
          filename="package://titaV2/meshes/left_wheel.STL" />
      </geometry>
    </collision>
  </link>
  <joint
    name="left_ankle_joint"
    type="continuous">
    <origin
      xyz="0.2 0 0"
      rpy="0 0 0" />
    <parent
      link="left_calf" />
    <child
      link="left_wheel" />
    <axis
      xyz="0 0 1" />
  </joint>
  <link
    name="right_hip">
    <inertial>
      <origin
        xyz="4.4311E-05 0.014041 0.0027491"
        rpy="0 0 0" />
      <mass
        value="1.9732" />
      <inertia
        ixx="0.002746"
        ixy="2.2481E-07"
        ixz="-4.8998E-07"
        iyy="0.0040655"
        iyz="-3.5899E-05"
        izz="0.0021042" />
    </inertial>
    <visual>
      <origin
        xyz="0 0 0"
        rpy="0 0 0" />
      <geometry>
        <mesh
          filename="package://titaV2/meshes/right_hip.STL" />
      </geometry>
      <material
        name="">
        <color
          rgba="0.75294 0.75294 0.75294 1" />
      </material>
    </visual>
    <collision>
      <origin
        xyz="0 0 0"
        rpy="0 0 0" />
      <geometry>
        <mesh
          filename="package://titaV2/meshes/right_hip.STL" />
      </geometry>
    </collision>
  </link>
  <joint
    name="right_hip_abduction_joint"
    type="revolute">
    <origin
      xyz="0 -0.0895 0"
      rpy="0 1.5708 0" />
    <parent
      link="pelvis" />
    <child
      link="right_hip" />
    <axis
      xyz="0 0 1" />
    <limit
      lower="-1.57"
      upper="1.57"
      effort="0"
      velocity="0" />
  </joint>
  <link
    name="right_thigh">
    <inertial>
      <origin
        xyz="0.018988 0.00090795 0.091109"
        rpy="0 0 0" />
      <mass
        value="2.365" />
      <inertia
        ixx="0.0024783"
        ixy="-0.00013332"
        ixz="-0.00010721"
        iyy="0.0052682"
        iyz="-5.356E-06"
        izz="0.0067965" />
    </inertial>
    <visual>
      <origin
        xyz="0 0 0"
        rpy="0 0 0" />
      <geometry>
        <mesh
          filename="package://titaV2/meshes/right_thigh.STL" />
      </geometry>
      <material
        name="">
        <color
          rgba="0.75294 0.75294 0.75294 1" />
      </material>
    </visual>
    <collision>
      <origin
        xyz="0 0 0"
        rpy="0 0 0" />
      <geometry>
        <mesh
          filename="package://titaV2/meshes/right_thigh.STL" />
      </geometry>
    </collision>
  </link>
  <joint
    name="right_hip_flexion_joint"
    type="revolute">
    <origin
      xyz="0 -0.1826 0"
      rpy="-1.5708 0 0" />
    <parent
      link="right_hip" />
    <child
      link="right_thigh" />
    <axis
      xyz="0 0 1" />
    <limit
      lower="-1.57"
      upper="1.57"
      effort="0"
      velocity="0" />
  </joint>
  <link
    name="right_calf">
    <inertial>
      <origin
        xyz="0.12103 0.0091003 0.05039"
        rpy="0 0 0" />
      <mass
        value="0.6116" />
      <inertia
        ixx="0.00026444"
        ixy="0.00018202"
        ixz="2.3441E-05"
        iyy="0.0021602"
        iyz="3.2666E-07"
        izz="0.0023188" />
    </inertial>
    <visual>
      <origin
        xyz="0 0 0"
        rpy="0 0 0" />
      <geometry>
        <mesh
          filename="package://titaV2/meshes/right_calf.STL" />
      </geometry>
      <material
        name="">
        <color
          rgba="0.75294 0.75294 0.75294 1" />
      </material>
    </visual>
    <collision>
      <origin
        xyz="0 0 0"
        rpy="0 0 0" />
      <geometry>
        <mesh
          filename="package://titaV2/meshes/right_calf.STL" />
      </geometry>
    </collision>
  </link>
  <joint
    name="right_knee_joint"
    type="revolute">
    <origin
      xyz="0.2 0 0"
      rpy="0 0 0" />
    <parent
      link="right_thigh" />
    <child
      link="right_calf" />
    <axis
      xyz="0 0 1" />
    <limit
      lower="-2"
      upper="1"
      effort="0"
      velocity="0" />
  </joint>
  <link
    name="right_wheel">
    <inertial>
      <origin
        xyz="-1.4534E-07 4.1544E-05 0.0018445"
        rpy="0 0 0" />
      <mass
        value="1.5377" />
      <inertia
        ixx="0.003086"
        ixy="4.7536E-08"
        ixz="3.5434E-08"
        iyy="0.003086"
        iyz="-4.621E-08"
        izz="0.0059413" />
    </inertial>
    <visual>
      <origin
        xyz="0 0 0"
        rpy="0 0 0" />
      <geometry>
        <mesh
          filename="package://titaV2/meshes/right_wheel.STL" />
      </geometry>
      <material
        name="">
        <color
          rgba="0.69804 0.69804 0.69804 1" />
      </material>
    </visual>
    <collision>
      <origin
        xyz="0 0 0"
        rpy="0 0 0" />
      <geometry>
        <mesh
          filename="package://titaV2/meshes/right_wheel.STL" />
      </geometry>
    </collision>
  </link>
  <joint
    name="right_ankle_joint"
    type="continuous">
    <origin
      xyz="0.2 0 0"
      rpy="0 0 0" />
    <parent
      link="right_calf" />
    <child
      link="right_wheel" />
    <axis
      xyz="0 0 1" />
  </joint>
</robot>