#VRML_SIM R2022b utf8
# license: Apache License 2.0
# license url: http://www.apache.org/licenses/LICENSE-2.0
# This is a proto file for Webots for the TitaV2
# Extracted from: ../urdfs/urdf/titaV2_closechain.urdf

PROTO TitaV2 [
  field  SFVec3f     translation     0 0 0
  field  SFRotation  rotation        0 0 1 0
  field  SFString    name            "TitaV2"  # Is `Robot.name`.
  field  SFString    controller      "void"    # Is `Robot.controller`.
  field  MFString    controllerArgs  []        # Is `Robot.controllerArgs`.
  field  SFString    customData      ""        # Is `Robot.customData`.
  field  SFBool      supervisor      FALSE     # Is `Robot.supervisor`.
  field  SFBool      synchronization TRUE      # Is `Robot.synchronization`.
  field  SFBool      selfCollision   FALSE     # Is `Robot.selfCollision`.
]
{
  Robot {
    translation IS translation
    rotation IS rotation
    controller IS controller
    controllerArgs IS controllerArgs
    customData IS customData
    supervisor IS supervisor
    synchronization IS synchronization
    selfCollision IS selfCollision
    children [
      Shape {
        appearance DEF pelvis_material PBRAppearance {
          baseColor 0.752940 0.752940 0.752940
          roughness 1.000000
          metalness 0
        }
        geometry DEF pelvis Mesh {
          url "../urdfs/meshes/pelvis.STL"
        }
      }
      HingeJoint {
        jointParameters HingeJointParameters {
          axis 1.000000 0.000000 -0.000004
          anchor 0.000000 0.089500 0.000000
        }
        device [
          RotationalMotor {
            name "left_hip_abduction_joint"
            minPosition -1.57
            maxPosition 1.57
            maxTorque 10000
          }
          PositionSensor {
            name "left_hip_abduction_joint_sensor"
          }
        ]
        endPoint Solid {
          translation 0.000000 0.089500 0.000000
          rotation 0.000000 1.000000 0.000000 1.570800
          children [
            Shape {
              appearance DEF left_hip_material PBRAppearance {
                baseColor 0.752940 0.752940 0.752940
                roughness 1.000000
                metalness 0
              }
              geometry DEF left_hip Mesh {
                url "../urdfs/meshes/left_hip.STL"
              }
            }
            HingeJoint {
              jointParameters HingeJointParameters {
                axis 0.000000 1.000000 -0.000004
                anchor 0.000000 0.182600 0.000000
              }
              device [
                RotationalMotor {
                  name "left_hip_flexion_joint"
                  minPosition -1.57
                  maxPosition 1.57
                  maxTorque 10000
                }
                PositionSensor {
                  name "left_hip_flexion_joint_sensor"
                }
              ]
              endPoint Solid {
                translation 0.000000 0.182600 0.000000
                rotation -1.000000 0.000000 0.000000 1.570800
                children [
                  Shape {
                    appearance DEF left_thigh_material PBRAppearance {
                      baseColor 0.752940 0.752940 0.752940
                      roughness 1.000000
                      metalness 0
                    }
                    geometry DEF left_thigh Mesh {
                      url "../urdfs/meshes/left_thigh.STL"
                    }
                  }
                  HingeJoint {
                    jointParameters HingeJointParameters {
                      axis 0.000000 -0.000000 1.000000
                      anchor 0.200000 0.000000 0.000000
                    }
                    device [
                      RotationalMotor {
                        name "left_knee_joint"
                        minPosition -2.0
                        maxPosition 1.0
                        maxTorque 10000
                      }
                      PositionSensor {
                        name "left_knee_joint_sensor"
                      }
                    ]
                    endPoint Solid {
                      translation 0.200000 0.000000 0.000000
                      rotation 0.000000 0.000000 -1.000000 1.570800
                      children [
                        Shape {
                          appearance DEF left_calf_material PBRAppearance {
                            baseColor 0.752940 0.752940 0.752940
                            roughness 1.000000
                            metalness 0
                          }
                          geometry DEF left_calf Mesh {
                            url "../urdfs/meshes/left_calf.STL"
                          }
                        }
                        HingeJoint {
                          jointParameters HingeJointParameters {
                            axis 0.000000 0.000000 1.000000
                            anchor 0.200000 0.000000 0.000000
                          }
                          device [
                            RotationalMotor {
                              name "left_ankle_joint"
                              maxTorque 10000
                            }
                            PositionSensor {
                              name "left_ankle_joint_sensor"
                            }
                          ]
                          endPoint Solid {
                            translation 0.200000 0.000000 0.000000
                            children [
                              Shape {
                                appearance DEF left_wheel_material PBRAppearance {
                                  baseColor 0.698040 0.698040 0.698040
                                  roughness 1.000000
                                  metalness 0
                                }
                                geometry DEF left_wheel Mesh {
                                  url "../urdfs/meshes/left_wheel.STL"
                                }
                              }
                            ]
                            name "left_wheel"
                            boundingObject USE left_wheel
                            physics Physics {
                              density -1
                              mass 1.537600
                              centerOfMass [ -0.000016 0.000206 -0.001793 ]
                              inertiaMatrix [
                                3.161600e-03 3.156900e-03 6.168900e-03
                                1.632400e-07 -4.403400e-08 -2.220700e-06
                              ]
                            }
                          }
                        }
                        HingeJoint {
                          jointParameters HingeJointParameters {
                            axis 0.000000 -0.000000 1.000000
                            anchor -0.023182 -0.006212 0.000000
                          }
                          device [
                            RotationalMotor {
                              name "left_calf_bar_joint"
                              maxTorque 10000
                            }
                            PositionSensor {
                              name "left_calf_bar_joint_sensor"
                            }
                          ]
                          endPoint Solid {
                            translation -0.023182 -0.006212 0.000000
                            rotation 0.000000 0.000000 -1.000000 1.570800
                            children [
                              Shape {
                                appearance DEF left_bar_material PBRAppearance {
                                  baseColor 0.647060 0.619610 0.588240
                                  roughness 1.000000
                                  metalness 0
                                }
                                geometry DEF left_bar Mesh {
                                  url "../urdfs/meshes/left_bar.STL"
                                }
                              }
                              HingeJoint {
                                jointParameters HingeJointParameters {
                                  axis 0.000000 0.000000 1.000000
                                  anchor 0.200000 0.000000 0.000000
                                }
                                device [
                                  RotationalMotor {
                                    name "left_bar_crank_joint"
                                    maxTorque 10000
                                  }
                                  PositionSensor {
                                    name "left_bar_crank_joint_sensor"
                                  }
                                ]
                                endPoint Solid {
                                  translation 0.200000 0.000000 0.000000
                                  rotation 0.000000 0.000000 1.000000 1.832600
                                  children [
                                    Shape {
                                      appearance DEF left_crank_material PBRAppearance {
                                        baseColor 0.647060 0.619610 0.588240
                                        roughness 1.000000
                                        metalness 0
                                      }
                                      geometry DEF left_crank Mesh {
                                        url "../urdfs/meshes/left_crank.STL"
                                      }
                                    }
                                  ]
                                  name "left_crank"
                                  boundingObject USE left_crank
                                  physics Physics {
                                    density -1
                                    mass 0.206950
                                    centerOfMass [ 0.017241 0.001522 -0.060973 ]
                                    inertiaMatrix [
                                      3.834500e-05 5.811200e-05 7.009300e-05
                                      4.989900e-07 5.016900e-06 -2.837300e-06
                                    ]
                                  }
                                }
                              }
                            ]
                            name "left_bar"
                            boundingObject USE left_bar
                            physics Physics {
                              density -1
                              mass 0.145120
                              centerOfMass [ 0.102720 0.000000 -0.056316 ]
                              inertiaMatrix [
                                3.257900e-06 6.146000e-04 6.163100e-04
                                2.522400e-20 -2.385500e-07 6.355200e-22
                              ]
                            }
                          }
                        }
                      ]
                      name "left_calf"
                      boundingObject USE left_calf
                      physics Physics {
                        density -1
                        mass 0.611600
                        centerOfMass [ 0.121030 0.009076 -0.050402 ]
                        inertiaMatrix [
                          2.645100e-04 2.160100e-03 2.318800e-03
                          1.824000e-04 -2.343900e-05 -3.221100e-07
                        ]
                      }
                    }
                  }
                ]
                name "left_thigh"
                boundingObject USE left_thigh
                physics Physics {
                  density -1
                  mass 2.365000
                  centerOfMass [ 0.019003 0.000924 -0.091109 ]
                  inertiaMatrix [
                    2.477700e-03 5.268700e-03 6.796400e-03
                    -1.333200e-04 1.071300e-04 5.269300e-06
                  ]
                }
              }
            }
          ]
          name "left_hip"
          boundingObject USE left_hip
          physics Physics {
            density -1
            mass 1.973200
            centerOfMass [ -0.000044 -0.014041 0.002749 ]
            inertiaMatrix [
              2.746000e-03 4.065500e-03 2.104200e-03
              2.248100e-07 4.899800e-07 3.589900e-05
            ]
          }
        }
      }
      HingeJoint {
        jointParameters HingeJointParameters {
          axis 1.000000 0.000000 -0.000004
          anchor 0.000000 -0.089500 0.000000
        }
        device [
          RotationalMotor {
            name "right_hip_abduction_joint"
            minPosition -1.57
            maxPosition 1.57
            maxTorque 10000
          }
          PositionSensor {
            name "right_hip_abduction_joint_sensor"
          }
        ]
        endPoint Solid {
          translation 0.000000 -0.089500 0.000000
          rotation 0.000000 1.000000 0.000000 1.570800
          children [
            Shape {
              appearance DEF right_hip_material PBRAppearance {
                baseColor 0.752940 0.752940 0.752940
                roughness 1.000000
                metalness 0
              }
              geometry DEF right_hip Mesh {
                url "../urdfs/meshes/right_hip.STL"
              }
            }
            HingeJoint {
              jointParameters HingeJointParameters {
                axis 0.000000 1.000000 -0.000004
                anchor 0.000000 -0.182600 0.000000
              }
              device [
                RotationalMotor {
                  name "right_hip_flexion_joint"
                  minPosition -1.57
                  maxPosition 1.57
                  maxTorque 10000
                }
                PositionSensor {
                  name "right_hip_flexion_joint_sensor"
                }
              ]
              endPoint Solid {
                translation 0.000000 -0.182600 0.000000
                rotation -1.000000 0.000000 0.000000 1.570800
                children [
                  Shape {
                    appearance DEF right_thigh_material PBRAppearance {
                      baseColor 0.752940 0.752940 0.752940
                      roughness 1.000000
                      metalness 0
                    }
                    geometry DEF right_thigh Mesh {
                      url "../urdfs/meshes/right_thigh.STL"
                    }
                  }
                  HingeJoint {
                    jointParameters HingeJointParameters {
                      axis 0.000000 -0.000000 1.000000
                      anchor 0.200000 0.000000 0.000000
                    }
                    device [
                      RotationalMotor {
                        name "right_knee_joint"
                        minPosition -2.0
                        maxPosition 1.0
                        maxTorque 10000
                      }
                      PositionSensor {
                        name "right_knee_joint_sensor"
                      }
                    ]
                    endPoint Solid {
                      translation 0.200000 0.000000 0.000000
                      rotation 0.000000 0.000000 -1.000000 1.570800
                      children [
                        Shape {
                          appearance DEF right_calf_material PBRAppearance {
                            baseColor 0.752940 0.752940 0.752940
                            roughness 1.000000
                            metalness 0
                          }
                          geometry DEF right_calf Mesh {
                            url "../urdfs/meshes/right_calf.STL"
                          }
                        }
                        HingeJoint {
                          jointParameters HingeJointParameters {
                            axis 0.000000 0.000000 1.000000
                            anchor 0.200000 0.000000 0.000000
                          }
                          device [
                            RotationalMotor {
                              name "right_ankle_joint"
                              maxTorque 10000
                            }
                            PositionSensor {
                              name "right_ankle_joint_sensor"
                            }
                          ]
                          endPoint Solid {
                            translation 0.200000 0.000000 0.000000
                            children [
                              Shape {
                                appearance DEF right_wheel_material PBRAppearance {
                                  baseColor 0.698040 0.698040 0.698040
                                  roughness 1.000000
                                  metalness 0
                                }
                                geometry DEF right_wheel Mesh {
                                  url "../urdfs/meshes/right_wheel.STL"
                                }
                              }
                            ]
                            name "right_wheel"
                            boundingObject USE right_wheel
                            physics Physics {
                              density -1
                              mass 1.537700
                              centerOfMass [ -0.000000 0.000042 0.001845 ]
                              inertiaMatrix [
                                3.086000e-03 3.086000e-03 5.941300e-03
                                4.753600e-08 3.543400e-08 -4.621000e-08
                              ]
                            }
                          }
                        }
                        HingeJoint {
                          jointParameters HingeJointParameters {
                            axis 0.000000 -0.000000 1.000000
                            anchor -0.023182 -0.006212 0.000000
                          }
                          device [
                            RotationalMotor {
                              name "right_calf_bar_joint"
                              maxTorque 10000
                            }
                            PositionSensor {
                              name "right_calf_bar_joint_sensor"
                            }
                          ]
                          endPoint Solid {
                            translation -0.023182 -0.006212 0.000000
                            rotation 0.000000 0.000000 -1.000000 1.570800
                            children [
                              Shape {
                                appearance DEF right_bar_material PBRAppearance {
                                  baseColor 0.647060 0.619610 0.588240
                                  roughness 1.000000
                                  metalness 0
                                }
                                geometry DEF right_bar Mesh {
                                  url "../urdfs/meshes/right_bar.STL"
                                }
                              }
                              HingeJoint {
                                jointParameters HingeJointParameters {
                                  axis 0.000000 0.000000 1.000000
                                  anchor 0.200000 0.000000 0.000000
                                }
                                device [
                                  RotationalMotor {
                                    name "right_bar_crank_joint"
                                    maxTorque 10000
                                  }
                                  PositionSensor {
                                    name "right_bar_crank_joint_sensor"
                                  }
                                ]
                                endPoint Solid {
                                  translation 0.200000 0.000000 0.000000
                                  rotation 0.000000 0.000000 1.000000 1.832600
                                  children [
                                    Shape {
                                      appearance DEF right_crank_material PBRAppearance {
                                        baseColor 0.647060 0.619610 0.588240
                                        roughness 1.000000
                                        metalness 0
                                      }
                                      geometry DEF right_crank Mesh {
                                        url "../urdfs/meshes/right_crank.STL"
                                      }
                                    }
                                  ]
                                  name "right_crank"
                                  boundingObject USE right_crank
                                  physics Physics {
                                    density -1
                                    mass 0.206950
                                    centerOfMass [ 0.017241 -0.001523 0.060973 ]
                                    inertiaMatrix [
                                      3.834600e-05 5.811200e-05 7.009300e-05
                                      -5.030200e-07 -5.016300e-06 -2.838300e-06
                                    ]
                                  }
                                }
                              }
                            ]
                            name "right_bar"
                            boundingObject USE right_bar
                            physics Physics {
                              density -1
                              mass 0.145120
                              centerOfMass [ 0.102730 0.000001 0.056284 ]
                              inertiaMatrix [
                                3.257900e-06 6.146000e-04 6.163100e-04
                                -1.802000e-17 -2.385500e-07 -7.747700e-21
                              ]
                            }
                          }
                        }
                      ]
                      name "right_calf"
                      boundingObject USE right_calf
                      physics Physics {
                        density -1
                        mass 0.611600
                        centerOfMass [ 0.121030 0.009100 0.050390 ]
                        inertiaMatrix [
                          2.644400e-04 2.160200e-03 2.318800e-03
                          1.820200e-04 2.344100e-05 3.266600e-07
                        ]
                      }
                    }
                  }
                ]
                name "right_thigh"
                boundingObject USE right_thigh
                physics Physics {
                  density -1
                  mass 2.365000
                  centerOfMass [ 0.018988 0.000908 0.091109 ]
                  inertiaMatrix [
                    2.478300e-03 5.268200e-03 6.796500e-03
                    -1.333200e-04 -1.072100e-04 -5.356000e-06
                  ]
                }
              }
            }
          ]
          name "right_hip"
          boundingObject USE right_hip
          physics Physics {
            density -1
            mass 1.973200
            centerOfMass [ 0.000044 0.014041 0.002749 ]
            inertiaMatrix [
              2.746000e-03 4.065500e-03 2.104200e-03
              2.248100e-07 -4.899800e-07 -3.589900e-05
            ]
          }
        }
      }
    ]
    name IS name
    boundingObject USE pelvis
    physics Physics {
      density -1
      mass 11.637000
      centerOfMass [ -0.002847 -0.000372 0.018090 ]
      inertiaMatrix [
        4.781100e-02 3.145600e-02 5.742900e-02
        -1.140200e-05 6.116000e-04 1.497100e-05
      ]
    }
  }
}
